<sdf version='1.7'>
  <world name='default'>
    <plugin name='mrs_gazebo_static_transform_republisher_plugin' filename='libMRSGazeboStaticTransformRepublisher.so'/>
    <spherical_coordinates>
      <surface_model>EARTH_WGS84</surface_model>
      <latitude_deg>47.3977</latitude_deg>
      <longitude_deg>8.54559</longitude_deg>
      <elevation>0</elevation>
      <heading_deg>0</heading_deg>
    </spherical_coordinates>
    <physics name='default_physics' default='0' type='ode'>
      <ode>
        <solver>
          <type>quick</type>
          <iters>10</iters>
          <sor>1.3</sor>
          <use_dynamic_moi_rescaling>0</use_dynamic_moi_rescaling>
        </solver>
        <constraints>
          <cfm>0</cfm>
          <erp>0.2</erp>
          <contact_max_correcting_vel>1000</contact_max_correcting_vel>
          <contact_surface_layer>0.001</contact_surface_layer>
        </constraints>
      </ode>
      <max_step_size>0.004</max_step_size>
      <real_time_factor>1</real_time_factor>
      <real_time_update_rate>250</real_time_update_rate>
    </physics>
    <scene>
      <shadows>0</shadows>
      <sky>
        <clouds/>
      </sky>
      <ambient>0.4 0.4 0.4 1</ambient>
      <background>0.7 0.7 0.7 1</background>
    </scene>
    <light name='sun' type='directional'>
      <pose>0 0 1000 0.4 0.2 0</pose>
      <diffuse>1 1 1 1</diffuse>
      <specular>0.6 0.6 0.6 1</specular>
      <direction>0.1 0.1 -0.9</direction>
      <attenuation>
        <range>20</range>
        <constant>0.5</constant>
        <linear>0.01</linear>
        <quadratic>0.001</quadratic>
      </attenuation>
      <cast_shadows>1</cast_shadows>
      <spot>
        <inner_angle>0</inner_angle>
        <outer_angle>0</outer_angle>
        <falloff>0</falloff>
      </spot>
    </light>
    <model name='ground_plane'>
      <static>1</static>
      <link name='link'>
        <collision name='collision'>
          <pose>0 0 0 0 -0 0</pose>
          <geometry>
            <plane>
              <normal>0 0 1</normal>
              <size>250 250</size>
            </plane>
          </geometry>
          <surface>
            <friction>
              <ode>
                <mu>1</mu>
                <mu2>1</mu2>
              </ode>
              <torsional>
                <ode/>
              </torsional>
            </friction>
            <contact>
              <ode/>
            </contact>
            <bounce/>
          </surface>
          <max_contacts>10</max_contacts>
        </collision>
        <visual name='grass'>
          <pose>0 0 0 0 -0 0</pose>
          <cast_shadows>0</cast_shadows>
          <geometry>
            <mesh>
              <uri>file://grass_plane/meshes/grass_plane.dae</uri>
            </mesh>
          </geometry>
        </visual>
        <self_collide>0</self_collide>
        <enable_wind>0</enable_wind>
        <kinematic>0</kinematic>
      </link>
    </model>
    <model name='the_void'>
      <static>1</static>
      <link name='link'>
        <pose>0 0 0.1 0 -0 0</pose>
        <visual name='the_void'>
          <pose>0 0 2 0 -0 0</pose>
          <geometry>
            <sphere>
              <radius>0.25</radius>
            </sphere>
          </geometry>
          <material>
            <script>
              <uri>file://media/materials/scripts/Gazebo.material</uri>
              <name>Gazebo/Black</name>
            </script>
          </material>
        </visual>
        <self_collide>0</self_collide>
        <enable_wind>0</enable_wind>
        <kinematic>0</kinematic>
      </link>
      <pose>-1000 -1000 0 0 -0 0</pose>
    </model>
    <gui fullscreen='0'>
      <camera name='camera'>
        <pose>-42.014 48.789 97.6018 0 1.04011 -0.015628</pose>
        <view_controller>orbit</view_controller>
        <projection_type>perspective</projection_type>
      </camera>
    </gui>
    <plugin name='mrs_gazebo_rviz_cam_synchronizer' filename='libMRSGazeboRvizCameraSynchronizer.so'>
      <target_frame_id>gazebo_user_camera</target_frame_id>
      <world_origin_frame_id>uav1/gps_origin</world_origin_frame_id>
      <frame_to_follow>uav1</frame_to_follow>
    </plugin>
    <gravity>0 0 -9.8066</gravity>
    <magnetic_field>6e-06 2.3e-05 -4.2e-05</magnetic_field>
    <atmosphere type='adiabatic'/>
    <wind/>
    <model name='uav1'>
      <link name='base_link'>
        <inertial>
          <pose>0 0 0 0 -0 0</pose>
          <mass>3.5</mass>
          <inertia>
            <ixx>0.0554167</ixx>
            <ixy>0</ixy>
            <ixz>0</ixz>
            <iyy>0.0554167</iyy>
            <iyz>0</iyz>
            <izz>0.109375</izz>
          </inertia>
        </inertial>
        <collision name='base_link_inertia_collision'>
          <pose>0 0 0 0 -0 0</pose>
          <geometry>
            <cylinder>
              <length>0.15</length>
              <radius>0.325</radius>
            </cylinder>
          </geometry>
          <surface>
            <contact>
              <ode>
                <min_depth>0.001</min_depth>
                <max_vel>0</max_vel>
              </ode>
            </contact>
            <friction>
              <ode/>
              <torsional>
                <ode/>
              </torsional>
            </friction>
            <bounce/>
          </surface>
          <max_contacts>10</max_contacts>
        </collision>
        <collision name='base_link_fixed_joint_lump__front_left_leg_clip_link_collision_1'>
          <pose>0.176777 0.176777 -0.135 0 -0 0.785398</pose>
          <geometry>
            <cylinder>
              <length>0.24</length>
              <radius>0.012</radius>
            </cylinder>
          </geometry>
          <surface>
            <contact>
              <ode>
                <min_depth>0.001</min_depth>
                <max_vel>0</max_vel>
              </ode>
            </contact>
            <friction>
              <ode/>
              <torsional>
                <ode/>
              </torsional>
            </friction>
            <bounce/>
          </surface>
          <max_contacts>10</max_contacts>
        </collision>
        <collision name='base_link_fixed_joint_lump__front_right_leg_clip_link_collision_2'>
          <pose>0.176777 -0.176777 -0.135 0 0 -0.785398</pose>
          <geometry>
            <cylinder>
              <length>0.24</length>
              <radius>0.012</radius>
            </cylinder>
          </geometry>
          <surface>
            <contact>
              <ode>
                <min_depth>0.001</min_depth>
                <max_vel>0</max_vel>
              </ode>
            </contact>
            <friction>
              <ode/>
              <torsional>
                <ode/>
              </torsional>
            </friction>
            <bounce/>
          </surface>
          <max_contacts>10</max_contacts>
        </collision>
        <collision name='base_link_fixed_joint_lump__rear_left_leg_clip_link_collision_3'>
          <pose>-0.176777 0.176777 -0.135 0 -0 2.35619</pose>
          <geometry>
            <cylinder>
              <length>0.24</length>
              <radius>0.012</radius>
            </cylinder>
          </geometry>
          <surface>
            <contact>
              <ode>
                <min_depth>0.001</min_depth>
                <max_vel>0</max_vel>
              </ode>
            </contact>
            <friction>
              <ode/>
              <torsional>
                <ode/>
              </torsional>
            </friction>
            <bounce/>
          </surface>
          <max_contacts>10</max_contacts>
        </collision>
        <collision name='base_link_fixed_joint_lump__rear_right_leg_clip_link_collision_4'>
          <pose>-0.176777 -0.176777 -0.135 0 0 -2.35619</pose>
          <geometry>
            <cylinder>
              <length>0.24</length>
              <radius>0.012</radius>
            </cylinder>
          </geometry>
          <surface>
            <contact>
              <ode>
                <min_depth>0.001</min_depth>
                <max_vel>0</max_vel>
              </ode>
            </contact>
            <friction>
              <ode/>
              <torsional>
                <ode/>
              </torsional>
            </friction>
            <bounce/>
          </surface>
          <max_contacts>10</max_contacts>
        </collision>
        <visual name='base_link_fixed_joint_lump__NUC_link_visual'>
          <pose>0.002 0 -0.255 0 -0 0</pose>
          <geometry>
            <mesh>
              <scale>1 1 1</scale>
              <uri>model://mrs_robots_description/meshes/tarot/t650/tarot_t650_nuc.dae</uri>
            </mesh>
          </geometry>
        </visual>
        <visual name='base_link_fixed_joint_lump__back_left_arm_link_visual_1'>
          <pose>0 0 -0.255 0 -0 2.35619</pose>
          <geometry>
            <mesh>
              <scale>1 1 1</scale>
              <uri>model://mrs_robots_description/meshes/tarot/t650/tarot_t650_arm_red.dae</uri>
            </mesh>
          </geometry>
        </visual>
        <visual name='base_link_fixed_joint_lump__back_left_rotor_link_visual_2'>
          <pose>-0.212132 0.212132 -0.021 0 -0 0</pose>
          <geometry>
            <mesh>
              <scale>1 1 1</scale>
              <uri>model://mrs_robots_description/meshes/tarot/t650/tarot_t650_motor_orange.dae</uri>
            </mesh>
          </geometry>
        </visual>
        <visual name='base_link_fixed_joint_lump__back_right_arm_link_visual_3'>
          <pose>0 0 -0.255 0 0 -2.35619</pose>
          <geometry>
            <mesh>
              <scale>1 1 1</scale>
              <uri>model://mrs_robots_description/meshes/tarot/t650/tarot_t650_arm_red.dae</uri>
            </mesh>
          </geometry>
        </visual>
        <visual name='base_link_fixed_joint_lump__back_right_rotor_link_visual_4'>
          <pose>-0.212132 -0.212132 -0.021 0 -0 0</pose>
          <geometry>
            <mesh>
              <scale>1 1 1</scale>
              <uri>model://mrs_robots_description/meshes/tarot/t650/tarot_t650_motor_orange.dae</uri>
            </mesh>
          </geometry>
        </visual>
        <visual name='base_link_fixed_joint_lump__battery_link_visual_5'>
          <pose>0 0 -0.0675 0 -0 0</pose>
          <geometry>
            <box>
              <size>0.16 0.065 0.044</size>
            </box>
          </geometry>
          <material>
            <script>
              <name>Gazebo/Grey</name>
              <uri>file://media/materials/scripts/gazebo.material</uri>
            </script>
          </material>
        </visual>
        <visual name='base_link_fixed_joint_lump__battery_mount_link_visual_6'>
          <pose>0 0 -0.036 0 -0 0</pose>
          <geometry>
            <mesh>
              <scale>0.001 0.001 0.001</scale>
              <uri>model://mrs_robots_description/meshes/tarot/t650/tarot_t650_battery_mount.dae</uri>
            </mesh>
          </geometry>
          <material>
            <script>
              <name>Gazebo/DarkGrey</name>
              <uri>file://media/materials/scripts/gazebo.material</uri>
            </script>
          </material>
        </visual>
        <visual name='base_link_fixed_joint_lump__bottom_board_link_visual_7'>
          <pose>0 0 -0.255 0 -0 0</pose>
          <geometry>
            <mesh>
              <scale>1 1 1</scale>
              <uri>model://mrs_robots_description/meshes/tarot/t650/tarot_t650_bottom_board.dae</uri>
            </mesh>
          </geometry>
        </visual>
        <visual name='base_link_fixed_joint_lump__front_left_arm_link_visual_8'>
          <pose>0 0 -0.255 0 -0 0.785398</pose>
          <geometry>
            <mesh>
              <scale>1 1 1</scale>
              <uri>model://mrs_robots_description/meshes/tarot/t650/tarot_t650_arm_black.dae</uri>
            </mesh>
          </geometry>
        </visual>
        <visual name='base_link_fixed_joint_lump__front_left_leg_clip_link_visual_9'>
          <pose>0.176777 0.176777 -0.135 0 -0 0.785398</pose>
          <geometry>
            <mesh>
              <scale>1 1 1</scale>
              <uri>model://mrs_robots_description/meshes/tarot/t650/tarot_t650_leg.dae</uri>
            </mesh>
          </geometry>
          <material>
            <script>
              <name>Gazebo/DarkGrey</name>
              <uri>file://media/materials/scripts/gazebo.material</uri>
            </script>
          </material>
        </visual>
        <visual name='base_link_fixed_joint_lump__front_left_rotor_link_visual_10'>
          <pose>0.212132 0.212132 -0.021 0 -0 0</pose>
          <geometry>
            <mesh>
              <scale>1 1 1</scale>
              <uri>model://mrs_robots_description/meshes/tarot/t650/tarot_t650_motor_black.dae</uri>
            </mesh>
          </geometry>
        </visual>
        <visual name='base_link_fixed_joint_lump__front_right_arm_link_visual_11'>
          <pose>0 0 -0.255 0 0 -0.785398</pose>
          <geometry>
            <mesh>
              <scale>1 1 1</scale>
              <uri>model://mrs_robots_description/meshes/tarot/t650/tarot_t650_arm_black.dae</uri>
            </mesh>
          </geometry>
        </visual>
        <visual name='base_link_fixed_joint_lump__front_right_leg_clip_link_visual_12'>
          <pose>0.176777 -0.176777 -0.135 0 0 -0.785398</pose>
          <geometry>
            <mesh>
              <scale>1 1 1</scale>
              <uri>model://mrs_robots_description/meshes/tarot/t650/tarot_t650_leg.dae</uri>
            </mesh>
          </geometry>
          <material>
            <script>
              <name>Gazebo/DarkGrey</name>
              <uri>file://media/materials/scripts/gazebo.material</uri>
            </script>
          </material>
        </visual>
        <visual name='base_link_fixed_joint_lump__front_right_rotor_link_visual_13'>
          <pose>0.212132 -0.212132 -0.021 0 -0 0</pose>
          <geometry>
            <mesh>
              <scale>1 1 1</scale>
              <uri>model://mrs_robots_description/meshes/tarot/t650/tarot_t650_motor_black.dae</uri>
            </mesh>
          </geometry>
        </visual>
        <visual name='base_link_fixed_joint_lump__pixhawk_link_visual_14'>
          <pose>0 0 -0.0075 0 -0 0</pose>
          <geometry>
            <mesh>
              <scale>1 1 1</scale>
              <uri>model://mrs_robots_description/meshes/sensors/pixhawk.dae</uri>
            </mesh>
          </geometry>
          <material>
            <script>
              <name>Gazebo/DarkGrey</name>
              <uri>file://media/materials/scripts/gazebo.material</uri>
            </script>
          </material>
        </visual>
        <visual name='base_link_fixed_joint_lump__rear_left_leg_clip_link_visual_15'>
          <pose>-0.176777 0.176777 -0.135 0 -0 2.35619</pose>
          <geometry>
            <mesh>
              <scale>1 1 1</scale>
              <uri>model://mrs_robots_description/meshes/tarot/t650/tarot_t650_leg.dae</uri>
            </mesh>
          </geometry>
          <material>
            <script>
              <name>Gazebo/Orange</name>
              <uri>file://media/materials/scripts/gazebo.material</uri>
            </script>
          </material>
        </visual>
        <visual name='base_link_fixed_joint_lump__rear_right_leg_clip_link_visual_16'>
          <pose>-0.176777 -0.176777 -0.135 0 0 -2.35619</pose>
          <geometry>
            <mesh>
              <scale>1 1 1</scale>
              <uri>model://mrs_robots_description/meshes/tarot/t650/tarot_t650_leg.dae</uri>
            </mesh>
          </geometry>
          <material>
            <script>
              <name>Gazebo/Orange</name>
              <uri>file://media/materials/scripts/gazebo.material</uri>
            </script>
          </material>
        </visual>
        <visual name='base_link_fixed_joint_lump__top_board_link_visual_17'>
          <pose>0 0 -0.255 0 -0 0</pose>
          <geometry>
            <mesh>
              <scale>1 1 1</scale>
              <uri>model://mrs_robots_description/meshes/tarot/t650/tarot_t650_top_board.dae</uri>
            </mesh>
          </geometry>
        </visual>
        <visual name='base_link_fixed_joint_lump__uav1/garmin_link_visual_18'>
          <pose>0 -0.221 -0.04 1.57079 1.57079 3.14159</pose>
          <geometry>
            <mesh>
              <scale>0.001 0.001 0.001</scale>
              <uri>model://mrs_robots_description/meshes/sensors/garmin_lidar_v3.stl</uri>
            </mesh>
          </geometry>
          <material>
            <script>
              <name>Gazebo/DarkGrey</name>
              <uri>file://media/materials/scripts/gazebo.material</uri>
            </script>
          </material>
        </visual>
        <visual name='base_link_fixed_joint_lump__uav1/rplidar_base_link_visual_19'>
          <pose>0 0 0.078 0 -0 3.14159</pose>
          <geometry>
            <mesh>
              <scale>0.001 0.001 0.001</scale>
              <uri>model://mrs_robots_description/meshes/sensors/rplidar.stl</uri>
            </mesh>
          </geometry>
          <material>
            <script>
              <name>Gazebo/FlatBlack</name>
              <uri>file://media/materials/scripts/gazebo.material</uri>
            </script>
          </material>
        </visual>
        <visual name='base_link_fixed_joint_lump__uav1/rplidar_visual_link_visual_20'>
          <pose>0 0 0.096 0 -0 0</pose>
          <geometry>
            <cylinder>
              <length>0.001</length>
              <radius>0.038</radius>
            </cylinder>
          </geometry>
          <material>
            <script>
              <name>Gazebo/Purple</name>
              <uri>file://media/materials/scripts/gazebo.material</uri>
            </script>
          </material>
        </visual>
        <sensor name='garmin' type='ray'>
          <update_rate>100</update_rate>
          <ray>
            <scan>
              <horizontal>
                <samples>5</samples>
                <resolution>1</resolution>
                <min_angle>-0.015</min_angle>
                <max_angle>0.015</max_angle>
              </horizontal>
              <vertical>
                <samples>5</samples>
                <resolution>1</resolution>
                <min_angle>-0.015</min_angle>
                <max_angle>0.015</max_angle>
              </vertical>
            </scan>
            <range>
              <min>0.1</min>
              <max>40</max>
              <resolution>0.005</resolution>
            </range>
          </ray>
          <plugin name='mrs_gazebo_rangefinder' filename='libMRSGazeboRangefinderPlugin.so'>
            <gaussianNoise>0.01</gaussianNoise>
            <alwaysOn>1</alwaysOn>
            <updateRate>100</updateRate>
            <topicName>garmin/range</topicName>
            <frameName>uav1/garmin</frameName>
            <fov>0.03</fov>
            <radiation>radiation</radiation>
            <parentFrameName>uav1/fcu</parentFrameName>
            <x>0.0</x>
            <y>-0.221</y>
            <z>-0.025</z>
            <roll>0</roll>
            <pitch>1.5707963267948966</pitch>
            <yaw>1.5707963267948966</yaw>
            <robotNamespace>/uav1/</robotNamespace>
          </plugin>
          <pose>0 -0.221 -0.025 3.14159 1.57079 -1.57079</pose>
        </sensor>
        <sensor name='rplidar' type='ray'>
          <visualize>0</visualize>
          <update_rate>20</update_rate>
          <ray>
            <scan>
              <horizontal>
                <samples>720</samples>
                <resolution>1</resolution>
                <min_angle>-3.12414</min_angle>
                <max_angle>3.12414</max_angle>
              </horizontal>
              <vertical>
                <samples>1</samples>
                <min_angle>0</min_angle>
                <max_angle>0</max_angle>
              </vertical>
            </scan>
            <range>
              <min>0.15</min>
              <max>14</max>
              <resolution>0.01</resolution>
            </range>
            <noise>
              <type>gaussian</type>
              <mean>0</mean>
              <stddev>0.01</stddev>
            </noise>
          </ray>
          <plugin name='mrs_gazebo_2dlidar' filename='libMRSGazebo2DLidarPlugin.so'>
            <topicName>rplidar/scan</topicName>
            <frameName>uav1/rplidar</frameName>
            <parentFrameName>uav1/fcu</parentFrameName>
            <x>0.0</x>
            <y>0.0</y>
            <z>0.107</z>
            <roll>0</roll>
            <pitch>0</pitch>
            <yaw>0</yaw>
            <robotNamespace>/uav1/</robotNamespace>
          </plugin>
          <pose>0 0 0.107 0 -0 0</pose>
        </sensor>
        <self_collide>0</self_collide>
        <enable_wind>0</enable_wind>
        <kinematic>0</kinematic>
      </link>
      <joint name='rotor_0_joint' type='revolute'>
        <pose relative_to='base_link'>0.212132 -0.212132 0.01 0 -0 0</pose>
        <parent>base_link</parent>
        <child>rotor_0</child>
        <axis>
          <xyz>0 0 1</xyz>
          <limit>
            <lower>-1e+16</lower>
            <upper>1e+16</upper>
          </limit>
          <dynamics>
            <spring_reference>0</spring_reference>
            <spring_stiffness>0</spring_stiffness>
          </dynamics>
        </axis>
      </joint>
      <link name='rotor_0'>
        <pose relative_to='rotor_0_joint'>0 0 0 0 -0 0</pose>
        <inertial>
          <pose>0 0 0 0 -0 0</pose>
          <mass>0.005</mass>
          <inertia>
            <ixx>0.0001</ixx>
            <ixy>0</ixy>
            <ixz>0</ixz>
            <iyy>0.0001</iyy>
            <iyz>0</iyz>
            <izz>0.0001</izz>
          </inertia>
        </inertial>
        <collision name='rotor_0_collision'>
          <pose>0 0 0 0 -0 0</pose>
          <geometry>
            <cylinder>
              <length>0.005</length>
              <radius>0.195</radius>
            </cylinder>
          </geometry>
          <max_contacts>10</max_contacts>
          <surface>
            <contact>
              <ode/>
            </contact>
            <bounce/>
            <friction>
              <torsional>
                <ode/>
              </torsional>
              <ode/>
            </friction>
          </surface>
        </collision>
        <visual name='rotor_0_visual'>
          <pose>0 0 0 0 -0 0</pose>
          <geometry>
            <mesh>
              <scale>1 1 1</scale>
              <uri>model://mrs_robots_description/meshes/tarot/t650/tarot_t650_prop_low_poly.dae</uri>
            </mesh>
          </geometry>
        </visual>
        <self_collide>0</self_collide>
        <enable_wind>0</enable_wind>
        <kinematic>0</kinematic>
      </link>
      <joint name='rotor_1_joint' type='revolute'>
        <pose relative_to='base_link'>-0.212132 0.212132 0.01 0 -0 0</pose>
        <parent>base_link</parent>
        <child>rotor_1</child>
        <axis>
          <xyz>0 0 1</xyz>
          <limit>
            <lower>-1e+16</lower>
            <upper>1e+16</upper>
          </limit>
          <dynamics>
            <spring_reference>0</spring_reference>
            <spring_stiffness>0</spring_stiffness>
          </dynamics>
        </axis>
      </joint>
      <link name='rotor_1'>
        <pose relative_to='rotor_1_joint'>0 0 0 0 -0 0</pose>
        <inertial>
          <pose>0 0 0 0 -0 0</pose>
          <mass>0.005</mass>
          <inertia>
            <ixx>0.0001</ixx>
            <ixy>0</ixy>
            <ixz>0</ixz>
            <iyy>0.0001</iyy>
            <iyz>0</iyz>
            <izz>0.0001</izz>
          </inertia>
        </inertial>
        <collision name='rotor_1_collision'>
          <pose>0 0 0 0 -0 0</pose>
          <geometry>
            <cylinder>
              <length>0.005</length>
              <radius>0.195</radius>
            </cylinder>
          </geometry>
          <max_contacts>10</max_contacts>
          <surface>
            <contact>
              <ode/>
            </contact>
            <bounce/>
            <friction>
              <torsional>
                <ode/>
              </torsional>
              <ode/>
            </friction>
          </surface>
        </collision>
        <visual name='rotor_1_visual'>
          <pose>0 0 0 0 -0 0</pose>
          <geometry>
            <mesh>
              <scale>1 1 1</scale>
              <uri>model://mrs_robots_description/meshes/tarot/t650/tarot_t650_prop_low_poly.dae</uri>
            </mesh>
          </geometry>
        </visual>
        <self_collide>0</self_collide>
        <enable_wind>0</enable_wind>
        <kinematic>0</kinematic>
      </link>
      <joint name='rotor_2_joint' type='revolute'>
        <pose relative_to='base_link'>0.212132 0.212132 0.01 0 -0 0</pose>
        <parent>base_link</parent>
        <child>rotor_2</child>
        <axis>
          <xyz>0 0 1</xyz>
          <limit>
            <lower>-1e+16</lower>
            <upper>1e+16</upper>
          </limit>
          <dynamics>
            <spring_reference>0</spring_reference>
            <spring_stiffness>0</spring_stiffness>
          </dynamics>
        </axis>
      </joint>
      <link name='rotor_2'>
        <pose relative_to='rotor_2_joint'>0 0 0 0 -0 0</pose>
        <inertial>
          <pose>0 0 0 0 -0 0</pose>
          <mass>0.005</mass>
          <inertia>
            <ixx>0.0001</ixx>
            <ixy>0</ixy>
            <ixz>0</ixz>
            <iyy>0.0001</iyy>
            <iyz>0</iyz>
            <izz>0.0001</izz>
          </inertia>
        </inertial>
        <collision name='rotor_2_collision'>
          <pose>0 0 0 0 -0 0</pose>
          <geometry>
            <cylinder>
              <length>0.005</length>
              <radius>0.195</radius>
            </cylinder>
          </geometry>
          <max_contacts>10</max_contacts>
          <surface>
            <contact>
              <ode/>
            </contact>
            <bounce/>
            <friction>
              <torsional>
                <ode/>
              </torsional>
              <ode/>
            </friction>
          </surface>
        </collision>
        <visual name='rotor_2_visual'>
          <pose>0 0 0 0 -0 0</pose>
          <geometry>
            <mesh>
              <scale>-1 1 1</scale>
              <uri>model://mrs_robots_description/meshes/tarot/t650/tarot_t650_prop_low_poly.dae</uri>
            </mesh>
          </geometry>
        </visual>
        <self_collide>0</self_collide>
        <enable_wind>0</enable_wind>
        <kinematic>0</kinematic>
      </link>
      <joint name='rotor_3_joint' type='revolute'>
        <pose relative_to='base_link'>-0.212132 -0.212132 0.01 0 -0 0</pose>
        <parent>base_link</parent>
        <child>rotor_3</child>
        <axis>
          <xyz>0 0 1</xyz>
          <limit>
            <lower>-1e+16</lower>
            <upper>1e+16</upper>
          </limit>
          <dynamics>
            <spring_reference>0</spring_reference>
            <spring_stiffness>0</spring_stiffness>
          </dynamics>
        </axis>
      </joint>
      <link name='rotor_3'>
        <pose relative_to='rotor_3_joint'>0 0 0 0 -0 0</pose>
        <inertial>
          <pose>0 0 0 0 -0 0</pose>
          <mass>0.005</mass>
          <inertia>
            <ixx>0.0001</ixx>
            <ixy>0</ixy>
            <ixz>0</ixz>
            <iyy>0.0001</iyy>
            <iyz>0</iyz>
            <izz>0.0001</izz>
          </inertia>
        </inertial>
        <collision name='rotor_3_collision'>
          <pose>0 0 0 0 -0 0</pose>
          <geometry>
            <cylinder>
              <length>0.005</length>
              <radius>0.195</radius>
            </cylinder>
          </geometry>
          <max_contacts>10</max_contacts>
          <surface>
            <contact>
              <ode/>
            </contact>
            <bounce/>
            <friction>
              <torsional>
                <ode/>
              </torsional>
              <ode/>
            </friction>
          </surface>
        </collision>
        <visual name='rotor_3_visual'>
          <pose>0 0 0 0 -0 0</pose>
          <geometry>
            <mesh>
              <scale>-1 1 1</scale>
              <uri>model://mrs_robots_description/meshes/tarot/t650/tarot_t650_prop_low_poly.dae</uri>
            </mesh>
          </geometry>
        </visual>
        <self_collide>0</self_collide>
        <enable_wind>0</enable_wind>
        <kinematic>0</kinematic>
      </link>
      <joint name='uav1/imu_joint' type='revolute'>
        <pose relative_to='base_link'>0 0 0 0 -0 0</pose>
        <parent>base_link</parent>
        <child>uav1/imu_link</child>
        <axis>
          <xyz>1 0 0</xyz>
          <limit>
            <lower>0</lower>
            <upper>0</upper>
            <effort>0</effort>
            <velocity>0</velocity>
          </limit>
          <dynamics>
            <spring_reference>0</spring_reference>
            <spring_stiffness>0</spring_stiffness>
          </dynamics>
        </axis>
      </joint>
      <link name='uav1/imu_link'>
        <pose relative_to='uav1/imu_joint'>0 0 0 0 -0 0</pose>
        <inertial>
          <pose>0 0 0 0 -0 0</pose>
          <mass>0.015</mass>
          <inertia>
            <ixx>1e-05</ixx>
            <ixy>0</ixy>
            <ixz>0</ixz>
            <iyy>1e-05</iyy>
            <iyz>0</iyz>
            <izz>1e-05</izz>
          </inertia>
        </inertial>
        <self_collide>0</self_collide>
        <enable_wind>0</enable_wind>
        <kinematic>0</kinematic>
      </link>
      <plugin name='rosbag' filename='libgazebo_multirotor_base_plugin.so'>
        <robotNamespace>uav1</robotNamespace>
        <linkName>base_link</linkName>
        <rotorVelocitySlowdownSim>0.0159236</rotorVelocitySlowdownSim>
      </plugin>
      <plugin name='front_right_motor_model' filename='libgazebo_motor_model.so'>
        <robotNamespace>uav1</robotNamespace>
        <jointName>rotor_0_joint</jointName>
        <linkName>rotor_0</linkName>
        <turningDirection>ccw</turningDirection>
        <timeConstantUp>0.0125</timeConstantUp>
        <timeConstantDown>0.025</timeConstantDown>
        <maxRotVelocity>1</maxRotVelocity>
        <motorConstant>23.0</motorConstant>
        <momentConstant>0.016</momentConstant>
        <commandSubTopic>/gazebo/command/motor_speed</commandSubTopic>
        <motorNumber>0</motorNumber>
        <rotorDragCoefficient>0.1</rotorDragCoefficient>
        <rollingMomentCoefficient>1e-06</rollingMomentCoefficient>
        <motorSpeedPubTopic>/motor_speed/0</motorSpeedPubTopic>
        <rotorVelocitySlowdownSim>0.0159236</rotorVelocitySlowdownSim>
      </plugin>
      <plugin name='back_left_motor_model' filename='libgazebo_motor_model.so'>
        <robotNamespace>uav1</robotNamespace>
        <jointName>rotor_1_joint</jointName>
        <linkName>rotor_1</linkName>
        <turningDirection>ccw</turningDirection>
        <timeConstantUp>0.0125</timeConstantUp>
        <timeConstantDown>0.025</timeConstantDown>
        <maxRotVelocity>1</maxRotVelocity>
        <motorConstant>23.0</motorConstant>
        <momentConstant>0.016</momentConstant>
        <commandSubTopic>/gazebo/command/motor_speed</commandSubTopic>
        <motorNumber>1</motorNumber>
        <rotorDragCoefficient>0.1</rotorDragCoefficient>
        <rollingMomentCoefficient>1e-06</rollingMomentCoefficient>
        <motorSpeedPubTopic>/motor_speed/1</motorSpeedPubTopic>
        <rotorVelocitySlowdownSim>0.0159236</rotorVelocitySlowdownSim>
      </plugin>
      <plugin name='front_left_motor_model' filename='libgazebo_motor_model.so'>
        <robotNamespace>uav1</robotNamespace>
        <jointName>rotor_2_joint</jointName>
        <linkName>rotor_2</linkName>
        <turningDirection>cw</turningDirection>
        <timeConstantUp>0.0125</timeConstantUp>
        <timeConstantDown>0.025</timeConstantDown>
        <maxRotVelocity>1</maxRotVelocity>
        <motorConstant>23.0</motorConstant>
        <momentConstant>0.016</momentConstant>
        <commandSubTopic>/gazebo/command/motor_speed</commandSubTopic>
        <motorNumber>2</motorNumber>
        <rotorDragCoefficient>0.1</rotorDragCoefficient>
        <rollingMomentCoefficient>1e-06</rollingMomentCoefficient>
        <motorSpeedPubTopic>/motor_speed/2</motorSpeedPubTopic>
        <rotorVelocitySlowdownSim>0.0159236</rotorVelocitySlowdownSim>
      </plugin>
      <plugin name='back_right_motor_model' filename='libgazebo_motor_model.so'>
        <robotNamespace>uav1</robotNamespace>
        <jointName>rotor_3_joint</jointName>
        <linkName>rotor_3</linkName>
        <turningDirection>cw</turningDirection>
        <timeConstantUp>0.0125</timeConstantUp>
        <timeConstantDown>0.025</timeConstantDown>
        <maxRotVelocity>1</maxRotVelocity>
        <motorConstant>23.0</motorConstant>
        <momentConstant>0.016</momentConstant>
        <commandSubTopic>/gazebo/command/motor_speed</commandSubTopic>
        <motorNumber>3</motorNumber>
        <rotorDragCoefficient>0.1</rotorDragCoefficient>
        <rollingMomentCoefficient>1e-06</rollingMomentCoefficient>
        <motorSpeedPubTopic>/motor_speed/3</motorSpeedPubTopic>
        <rotorVelocitySlowdownSim>0.0159236</rotorVelocitySlowdownSim>
      </plugin>
      <plugin name='mavlink_interface' filename='libgazebo_mavlink_interface.so'>
        <robotNamespace>uav1</robotNamespace>
        <imuSubTopic>/imu</imuSubTopic>
        <magSubTopic>/mag</magSubTopic>
        <baroSubTopic>/baro</baroSubTopic>
        <mavlink_addr>INADDR_ANY</mavlink_addr>
        <mavlink_udp_port>14561</mavlink_udp_port>
        <mavlink_tcp_port>4561</mavlink_tcp_port>
        <serialEnabled>0</serialEnabled>
        <serialDevice>/dev/ttyACM0</serialDevice>
        <baudRate>921600</baudRate>
        <qgc_addr>INADDR_ANY</qgc_addr>
        <qgc_udp_port>14550</qgc_udp_port>
        <sdk_addr>INADDR_ANY</sdk_addr>
        <sdk_udp_port>14540</sdk_udp_port>
        <hil_mode>0</hil_mode>
        <hil_state_level>0</hil_state_level>
        <vehicle_is_tailsitter>0</vehicle_is_tailsitter>
        <send_vision_estimation>0</send_vision_estimation>
        <send_odometry>0</send_odometry>
        <enable_lockstep>1</enable_lockstep>
        <use_tcp>1</use_tcp>
        <motorSpeedCommandPubTopic>/gazebo/command/motor_speed</motorSpeedCommandPubTopic>
        <control_channels>
          <channel name='rotor1'>
            <input_index>0</input_index>
            <input_offset>0</input_offset>
            <input_scaling>1</input_scaling>
            <zero_position_disarmed>0</zero_position_disarmed>
            <zero_position_armed>0.15</zero_position_armed>
            <joint_control_type>velocity</joint_control_type>
          </channel>
          <channel name='rotor2'>
            <input_index>1</input_index>
            <input_offset>0</input_offset>
            <input_scaling>1</input_scaling>
            <zero_position_disarmed>0</zero_position_disarmed>
            <zero_position_armed>0.15</zero_position_armed>
            <joint_control_type>velocity</joint_control_type>
          </channel>
          <channel name='rotor3'>
            <input_index>2</input_index>
            <input_offset>0</input_offset>
            <input_scaling>1</input_scaling>
            <zero_position_disarmed>0</zero_position_disarmed>
            <zero_position_armed>0.15</zero_position_armed>
            <joint_control_type>velocity</joint_control_type>
          </channel>
          <channel name='rotor4'>
            <input_index>3</input_index>
            <input_offset>0</input_offset>
            <input_scaling>1</input_scaling>
            <zero_position_disarmed>0</zero_position_disarmed>
            <zero_position_armed>0.15</zero_position_armed>
            <joint_control_type>velocity</joint_control_type>
          </channel>
          <channel name='rotor5'>
            <input_index>4</input_index>
            <input_offset>0</input_offset>
            <input_scaling>1</input_scaling>
            <zero_position_disarmed>0</zero_position_disarmed>
            <zero_position_armed>0.15</zero_position_armed>
            <joint_control_type>velocity</joint_control_type>
          </channel>
          <channel name='rotor6'>
            <input_index>5</input_index>
            <input_offset>0</input_offset>
            <input_scaling>1</input_scaling>
            <zero_position_disarmed>0</zero_position_disarmed>
            <zero_position_armed>0.15</zero_position_armed>
            <joint_control_type>velocity</joint_control_type>
          </channel>
          <channel name='rotor7'>
            <input_index>6</input_index>
            <input_offset>0</input_offset>
            <input_scaling>1</input_scaling>
            <zero_position_disarmed>0</zero_position_disarmed>
            <zero_position_armed>0.15</zero_position_armed>
            <joint_control_type>velocity</joint_control_type>
          </channel>
          <channel name='rotor8'>
            <input_index>7</input_index>
            <input_offset>0</input_offset>
            <input_scaling>1</input_scaling>
            <zero_position_disarmed>0</zero_position_disarmed>
            <zero_position_armed>0.15</zero_position_armed>
            <joint_control_type>velocity</joint_control_type>
          </channel>
        </control_channels>
      </plugin>
      <link name='gps0_link'>
        <pose>0 0 0 0 -0 0</pose>
        <inertial>
          <pose>0 0 0 0 -0 0</pose>
          <mass>0.01</mass>
          <inertia>
            <ixx>2.1733e-06</ixx>
            <ixy>0</ixy>
            <ixz>0</ixz>
            <iyy>2.1733e-06</iyy>
            <iyz>0</iyz>
            <izz>1.8e-07</izz>
          </inertia>
        </inertial>
        <sensor name='gps' type='gps'>
          <pose>0 0 0 0 -0 0</pose>
          <plugin name='gps_plugin' filename='libgazebo_gps_plugin.so'>
            <robotNamespace>uav1</robotNamespace>
            <gpsNoise>1</gpsNoise>
            <gpsXYRandomWalk>2.0</gpsXYRandomWalk>
            <gpsZRandomWalk>4.0</gpsZRandomWalk>
            <gpsXYNoiseDensity>0.0002</gpsXYNoiseDensity>
            <gpsZNoiseDensity>0.0004</gpsZNoiseDensity>
            <gpsVXYNoiseDensity>0.2</gpsVXYNoiseDensity>
            <gpsVZNoiseDensity>0.4</gpsVZNoiseDensity>
            <update_rate>10</update_rate>
            <topic>gps0</topic>
          </plugin>
          <gps/>
        </sensor>
        <self_collide>0</self_collide>
        <enable_wind>0</enable_wind>
        <kinematic>0</kinematic>
      </link>
      <joint name='gps0_joint' type='fixed'>
        <parent>base_link</parent>
        <child>gps0_link</child>
      </joint>
      <plugin name='magnetometer_plugin' filename='libMRSGazeboMagnetometerPlugin.so'>
        <robotNamespace>uav1</robotNamespace>
        <pubRate>100</pubRate>
        <noiseDensity>0.0004</noiseDensity>
        <randomWalk>6.4e-06</randomWalk>
        <biasCorrelationTime>600</biasCorrelationTime>
        <magTopic>/mag</magTopic>
      </plugin>
      <plugin name='groundtruth_plugin' filename='libgazebo_groundtruth_plugin.so'>
        <robotNamespace>uav1</robotNamespace>
        <homeLatitude>0.0</homeLatitude>
        <homeLongitude>0.0</homeLongitude>
        <homeAltitude>0.0</homeAltitude>
      </plugin>
      <plugin name='barometer_plugin' filename='libgazebo_barometer_plugin.so'>
        <robotNamespace>uav1</robotNamespace>
        <pubRate>50</pubRate>
        <baroTopic>/baro</baroTopic>
        <baroDriftPaPerSec>0</baroDriftPaPerSec>
      </plugin>
      <static>0</static>
      <plugin name='rotors_gazebo_imu_plugin' filename='libgazebo_imu_plugin.so'>
        <robotNamespace>uav1</robotNamespace>
        <linkName>uav1/imu_link</linkName>
        <imuTopic>/imu</imuTopic>
        <gyroscopeNoiseDensity>0.00018665</gyroscopeNoiseDensity>
        <gyroscopeRandomWalk>3.8785e-05</gyroscopeRandomWalk>
        <gyroscopeBiasCorrelationTime>1000.0</gyroscopeBiasCorrelationTime>
        <gyroscopeTurnOnBiasSigma>0.0087</gyroscopeTurnOnBiasSigma>
        <accelerometerNoiseDensity>0.00186</accelerometerNoiseDensity>
        <accelerometerRandomWalk>0.006</accelerometerRandomWalk>
        <accelerometerBiasCorrelationTime>300.0</accelerometerBiasCorrelationTime>
        <accelerometerTurnOnBiasSigma>0.196</accelerometerTurnOnBiasSigma>
      </plugin>
      <pose>-4 29.45 0.3 0 -0 0</pose>
    </model>
    <model name='uav2'>
      <link name='base_link'>
        <inertial>
          <pose>0 0 0 0 -0 0</pose>
          <mass>3.5</mass>
          <inertia>
            <ixx>0.0554167</ixx>
            <ixy>0</ixy>
            <ixz>0</ixz>
            <iyy>0.0554167</iyy>
            <iyz>0</iyz>
            <izz>0.109375</izz>
          </inertia>
        </inertial>
        <collision name='base_link_inertia_collision'>
          <pose>0 0 0 0 -0 0</pose>
          <geometry>
            <cylinder>
              <length>0.15</length>
              <radius>0.325</radius>
            </cylinder>
          </geometry>
          <surface>
            <contact>
              <ode>
                <min_depth>0.001</min_depth>
                <max_vel>0</max_vel>
              </ode>
            </contact>
            <friction>
              <ode/>
              <torsional>
                <ode/>
              </torsional>
            </friction>
            <bounce/>
          </surface>
          <max_contacts>10</max_contacts>
        </collision>
        <collision name='base_link_fixed_joint_lump__front_left_leg_clip_link_collision_1'>
          <pose>0.176777 0.176777 -0.135 0 -0 0.785398</pose>
          <geometry>
            <cylinder>
              <length>0.24</length>
              <radius>0.012</radius>
            </cylinder>
          </geometry>
          <surface>
            <contact>
              <ode>
                <min_depth>0.001</min_depth>
                <max_vel>0</max_vel>
              </ode>
            </contact>
            <friction>
              <ode/>
              <torsional>
                <ode/>
              </torsional>
            </friction>
            <bounce/>
          </surface>
          <max_contacts>10</max_contacts>
        </collision>
        <collision name='base_link_fixed_joint_lump__front_right_leg_clip_link_collision_2'>
          <pose>0.176777 -0.176777 -0.135 0 0 -0.785398</pose>
          <geometry>
            <cylinder>
              <length>0.24</length>
              <radius>0.012</radius>
            </cylinder>
          </geometry>
          <surface>
            <contact>
              <ode>
                <min_depth>0.001</min_depth>
                <max_vel>0</max_vel>
              </ode>
            </contact>
            <friction>
              <ode/>
              <torsional>
                <ode/>
              </torsional>
            </friction>
            <bounce/>
          </surface>
          <max_contacts>10</max_contacts>
        </collision>
        <collision name='base_link_fixed_joint_lump__rear_left_leg_clip_link_collision_3'>
          <pose>-0.176777 0.176777 -0.135 0 -0 2.35619</pose>
          <geometry>
            <cylinder>
              <length>0.24</length>
              <radius>0.012</radius>
            </cylinder>
          </geometry>
          <surface>
            <contact>
              <ode>
                <min_depth>0.001</min_depth>
                <max_vel>0</max_vel>
              </ode>
            </contact>
            <friction>
              <ode/>
              <torsional>
                <ode/>
              </torsional>
            </friction>
            <bounce/>
          </surface>
          <max_contacts>10</max_contacts>
        </collision>
        <collision name='base_link_fixed_joint_lump__rear_right_leg_clip_link_collision_4'>
          <pose>-0.176777 -0.176777 -0.135 0 0 -2.35619</pose>
          <geometry>
            <cylinder>
              <length>0.24</length>
              <radius>0.012</radius>
            </cylinder>
          </geometry>
          <surface>
            <contact>
              <ode>
                <min_depth>0.001</min_depth>
                <max_vel>0</max_vel>
              </ode>
            </contact>
            <friction>
              <ode/>
              <torsional>
                <ode/>
              </torsional>
            </friction>
            <bounce/>
          </surface>
          <max_contacts>10</max_contacts>
        </collision>
        <visual name='base_link_fixed_joint_lump__NUC_link_visual'>
          <pose>0.002 0 -0.255 0 -0 0</pose>
          <geometry>
            <mesh>
              <scale>1 1 1</scale>
              <uri>model://mrs_robots_description/meshes/tarot/t650/tarot_t650_nuc.dae</uri>
            </mesh>
          </geometry>
        </visual>
        <visual name='base_link_fixed_joint_lump__back_left_arm_link_visual_1'>
          <pose>0 0 -0.255 0 -0 2.35619</pose>
          <geometry>
            <mesh>
              <scale>1 1 1</scale>
              <uri>model://mrs_robots_description/meshes/tarot/t650/tarot_t650_arm_red.dae</uri>
            </mesh>
          </geometry>
        </visual>
        <visual name='base_link_fixed_joint_lump__back_left_rotor_link_visual_2'>
          <pose>-0.212132 0.212132 -0.021 0 -0 0</pose>
          <geometry>
            <mesh>
              <scale>1 1 1</scale>
              <uri>model://mrs_robots_description/meshes/tarot/t650/tarot_t650_motor_orange.dae</uri>
            </mesh>
          </geometry>
        </visual>
        <visual name='base_link_fixed_joint_lump__back_right_arm_link_visual_3'>
          <pose>0 0 -0.255 0 0 -2.35619</pose>
          <geometry>
            <mesh>
              <scale>1 1 1</scale>
              <uri>model://mrs_robots_description/meshes/tarot/t650/tarot_t650_arm_red.dae</uri>
            </mesh>
          </geometry>
        </visual>
        <visual name='base_link_fixed_joint_lump__back_right_rotor_link_visual_4'>
          <pose>-0.212132 -0.212132 -0.021 0 -0 0</pose>
          <geometry>
            <mesh>
              <scale>1 1 1</scale>
              <uri>model://mrs_robots_description/meshes/tarot/t650/tarot_t650_motor_orange.dae</uri>
            </mesh>
          </geometry>
        </visual>
        <visual name='base_link_fixed_joint_lump__battery_link_visual_5'>
          <pose>0 0 -0.0675 0 -0 0</pose>
          <geometry>
            <box>
              <size>0.16 0.065 0.044</size>
            </box>
          </geometry>
          <material>
            <script>
              <name>Gazebo/Grey</name>
              <uri>file://media/materials/scripts/gazebo.material</uri>
            </script>
          </material>
        </visual>
        <visual name='base_link_fixed_joint_lump__battery_mount_link_visual_6'>
          <pose>0 0 -0.036 0 -0 0</pose>
          <geometry>
            <mesh>
              <scale>0.001 0.001 0.001</scale>
              <uri>model://mrs_robots_description/meshes/tarot/t650/tarot_t650_battery_mount.dae</uri>
            </mesh>
          </geometry>
          <material>
            <script>
              <name>Gazebo/DarkGrey</name>
              <uri>file://media/materials/scripts/gazebo.material</uri>
            </script>
          </material>
        </visual>
        <visual name='base_link_fixed_joint_lump__bottom_board_link_visual_7'>
          <pose>0 0 -0.255 0 -0 0</pose>
          <geometry>
            <mesh>
              <scale>1 1 1</scale>
              <uri>model://mrs_robots_description/meshes/tarot/t650/tarot_t650_bottom_board.dae</uri>
            </mesh>
          </geometry>
        </visual>
        <visual name='base_link_fixed_joint_lump__front_left_arm_link_visual_8'>
          <pose>0 0 -0.255 0 -0 0.785398</pose>
          <geometry>
            <mesh>
              <scale>1 1 1</scale>
              <uri>model://mrs_robots_description/meshes/tarot/t650/tarot_t650_arm_black.dae</uri>
            </mesh>
          </geometry>
        </visual>
        <visual name='base_link_fixed_joint_lump__front_left_leg_clip_link_visual_9'>
          <pose>0.176777 0.176777 -0.135 0 -0 0.785398</pose>
          <geometry>
            <mesh>
              <scale>1 1 1</scale>
              <uri>model://mrs_robots_description/meshes/tarot/t650/tarot_t650_leg.dae</uri>
            </mesh>
          </geometry>
          <material>
            <script>
              <name>Gazebo/DarkGrey</name>
              <uri>file://media/materials/scripts/gazebo.material</uri>
            </script>
          </material>
        </visual>
        <visual name='base_link_fixed_joint_lump__front_left_rotor_link_visual_10'>
          <pose>0.212132 0.212132 -0.021 0 -0 0</pose>
          <geometry>
            <mesh>
              <scale>1 1 1</scale>
              <uri>model://mrs_robots_description/meshes/tarot/t650/tarot_t650_motor_black.dae</uri>
            </mesh>
          </geometry>
        </visual>
        <visual name='base_link_fixed_joint_lump__front_right_arm_link_visual_11'>
          <pose>0 0 -0.255 0 0 -0.785398</pose>
          <geometry>
            <mesh>
              <scale>1 1 1</scale>
              <uri>model://mrs_robots_description/meshes/tarot/t650/tarot_t650_arm_black.dae</uri>
            </mesh>
          </geometry>
        </visual>
        <visual name='base_link_fixed_joint_lump__front_right_leg_clip_link_visual_12'>
          <pose>0.176777 -0.176777 -0.135 0 0 -0.785398</pose>
          <geometry>
            <mesh>
              <scale>1 1 1</scale>
              <uri>model://mrs_robots_description/meshes/tarot/t650/tarot_t650_leg.dae</uri>
            </mesh>
          </geometry>
          <material>
            <script>
              <name>Gazebo/DarkGrey</name>
              <uri>file://media/materials/scripts/gazebo.material</uri>
            </script>
          </material>
        </visual>
        <visual name='base_link_fixed_joint_lump__front_right_rotor_link_visual_13'>
          <pose>0.212132 -0.212132 -0.021 0 -0 0</pose>
          <geometry>
            <mesh>
              <scale>1 1 1</scale>
              <uri>model://mrs_robots_description/meshes/tarot/t650/tarot_t650_motor_black.dae</uri>
            </mesh>
          </geometry>
        </visual>
        <visual name='base_link_fixed_joint_lump__pixhawk_link_visual_14'>
          <pose>0 0 -0.0075 0 -0 0</pose>
          <geometry>
            <mesh>
              <scale>1 1 1</scale>
              <uri>model://mrs_robots_description/meshes/sensors/pixhawk.dae</uri>
            </mesh>
          </geometry>
          <material>
            <script>
              <name>Gazebo/DarkGrey</name>
              <uri>file://media/materials/scripts/gazebo.material</uri>
            </script>
          </material>
        </visual>
        <visual name='base_link_fixed_joint_lump__rear_left_leg_clip_link_visual_15'>
          <pose>-0.176777 0.176777 -0.135 0 -0 2.35619</pose>
          <geometry>
            <mesh>
              <scale>1 1 1</scale>
              <uri>model://mrs_robots_description/meshes/tarot/t650/tarot_t650_leg.dae</uri>
            </mesh>
          </geometry>
          <material>
            <script>
              <name>Gazebo/Orange</name>
              <uri>file://media/materials/scripts/gazebo.material</uri>
            </script>
          </material>
        </visual>
        <visual name='base_link_fixed_joint_lump__rear_right_leg_clip_link_visual_16'>
          <pose>-0.176777 -0.176777 -0.135 0 0 -2.35619</pose>
          <geometry>
            <mesh>
              <scale>1 1 1</scale>
              <uri>model://mrs_robots_description/meshes/tarot/t650/tarot_t650_leg.dae</uri>
            </mesh>
          </geometry>
          <material>
            <script>
              <name>Gazebo/Orange</name>
              <uri>file://media/materials/scripts/gazebo.material</uri>
            </script>
          </material>
        </visual>
        <visual name='base_link_fixed_joint_lump__top_board_link_visual_17'>
          <pose>0 0 -0.255 0 -0 0</pose>
          <geometry>
            <mesh>
              <scale>1 1 1</scale>
              <uri>model://mrs_robots_description/meshes/tarot/t650/tarot_t650_top_board.dae</uri>
            </mesh>
          </geometry>
        </visual>
        <visual name='base_link_fixed_joint_lump__uav2/garmin_link_visual_18'>
          <pose>0 -0.221 -0.04 1.57079 1.57079 3.14159</pose>
          <geometry>
            <mesh>
              <scale>0.001 0.001 0.001</scale>
              <uri>model://mrs_robots_description/meshes/sensors/garmin_lidar_v3.stl</uri>
            </mesh>
          </geometry>
          <material>
            <script>
              <name>Gazebo/DarkGrey</name>
              <uri>file://media/materials/scripts/gazebo.material</uri>
            </script>
          </material>
        </visual>
        <visual name='base_link_fixed_joint_lump__uav2/rplidar_base_link_visual_19'>
          <pose>0 0 0.078 0 -0 3.14159</pose>
          <geometry>
            <mesh>
              <scale>0.001 0.001 0.001</scale>
              <uri>model://mrs_robots_description/meshes/sensors/rplidar.stl</uri>
            </mesh>
          </geometry>
          <material>
            <script>
              <name>Gazebo/FlatBlack</name>
              <uri>file://media/materials/scripts/gazebo.material</uri>
            </script>
          </material>
        </visual>
        <visual name='base_link_fixed_joint_lump__uav2/rplidar_visual_link_visual_20'>
          <pose>0 0 0.096 0 -0 0</pose>
          <geometry>
            <cylinder>
              <length>0.001</length>
              <radius>0.038</radius>
            </cylinder>
          </geometry>
          <material>
            <script>
              <name>Gazebo/Purple</name>
              <uri>file://media/materials/scripts/gazebo.material</uri>
            </script>
          </material>
        </visual>
        <sensor name='garmin' type='ray'>
          <update_rate>100</update_rate>
          <ray>
            <scan>
              <horizontal>
                <samples>5</samples>
                <resolution>1</resolution>
                <min_angle>-0.015</min_angle>
                <max_angle>0.015</max_angle>
              </horizontal>
              <vertical>
                <samples>5</samples>
                <resolution>1</resolution>
                <min_angle>-0.015</min_angle>
                <max_angle>0.015</max_angle>
              </vertical>
            </scan>
            <range>
              <min>0.1</min>
              <max>40</max>
              <resolution>0.005</resolution>
            </range>
          </ray>
          <plugin name='mrs_gazebo_rangefinder' filename='libMRSGazeboRangefinderPlugin.so'>
            <gaussianNoise>0.01</gaussianNoise>
            <alwaysOn>1</alwaysOn>
            <updateRate>100</updateRate>
            <topicName>garmin/range</topicName>
            <frameName>uav2/garmin</frameName>
            <fov>0.03</fov>
            <radiation>radiation</radiation>
            <parentFrameName>uav2/fcu</parentFrameName>
            <x>0.0</x>
            <y>-0.221</y>
            <z>-0.025</z>
            <roll>0</roll>
            <pitch>1.5707963267948966</pitch>
            <yaw>1.5707963267948966</yaw>
            <robotNamespace>/uav2/</robotNamespace>
          </plugin>
          <pose>0 -0.221 -0.025 3.14159 1.57079 -1.57079</pose>
        </sensor>
        <sensor name='rplidar' type='ray'>
          <visualize>0</visualize>
          <update_rate>20</update_rate>
          <ray>
            <scan>
              <horizontal>
                <samples>720</samples>
                <resolution>1</resolution>
                <min_angle>-3.12414</min_angle>
                <max_angle>3.12414</max_angle>
              </horizontal>
              <vertical>
                <samples>1</samples>
                <min_angle>0</min_angle>
                <max_angle>0</max_angle>
              </vertical>
            </scan>
            <range>
              <min>0.15</min>
              <max>14</max>
              <resolution>0.01</resolution>
            </range>
            <noise>
              <type>gaussian</type>
              <mean>0</mean>
              <stddev>0.01</stddev>
            </noise>
          </ray>
          <plugin name='mrs_gazebo_2dlidar' filename='libMRSGazebo2DLidarPlugin.so'>
            <topicName>rplidar/scan</topicName>
            <frameName>uav2/rplidar</frameName>
            <parentFrameName>uav2/fcu</parentFrameName>
            <x>0.0</x>
            <y>0.0</y>
            <z>0.107</z>
            <roll>0</roll>
            <pitch>0</pitch>
            <yaw>0</yaw>
            <robotNamespace>/uav2/</robotNamespace>
          </plugin>
          <pose>0 0 0.107 0 -0 0</pose>
        </sensor>
        <self_collide>0</self_collide>
        <enable_wind>0</enable_wind>
        <kinematic>0</kinematic>
      </link>
      <joint name='rotor_0_joint' type='revolute'>
        <pose relative_to='base_link'>0.212132 -0.212132 0.01 0 -0 0</pose>
        <parent>base_link</parent>
        <child>rotor_0</child>
        <axis>
          <xyz>0 0 1</xyz>
          <limit>
            <lower>-1e+16</lower>
            <upper>1e+16</upper>
          </limit>
          <dynamics>
            <spring_reference>0</spring_reference>
            <spring_stiffness>0</spring_stiffness>
          </dynamics>
        </axis>
      </joint>
      <link name='rotor_0'>
        <pose relative_to='rotor_0_joint'>0 0 0 0 -0 0</pose>
        <inertial>
          <pose>0 0 0 0 -0 0</pose>
          <mass>0.005</mass>
          <inertia>
            <ixx>0.0001</ixx>
            <ixy>0</ixy>
            <ixz>0</ixz>
            <iyy>0.0001</iyy>
            <iyz>0</iyz>
            <izz>0.0001</izz>
          </inertia>
        </inertial>
        <collision name='rotor_0_collision'>
          <pose>0 0 0 0 -0 0</pose>
          <geometry>
            <cylinder>
              <length>0.005</length>
              <radius>0.195</radius>
            </cylinder>
          </geometry>
          <max_contacts>10</max_contacts>
          <surface>
            <contact>
              <ode/>
            </contact>
            <bounce/>
            <friction>
              <torsional>
                <ode/>
              </torsional>
              <ode/>
            </friction>
          </surface>
        </collision>
        <visual name='rotor_0_visual'>
          <pose>0 0 0 0 -0 0</pose>
          <geometry>
            <mesh>
              <scale>1 1 1</scale>
              <uri>model://mrs_robots_description/meshes/tarot/t650/tarot_t650_prop_low_poly.dae</uri>
            </mesh>
          </geometry>
        </visual>
        <self_collide>0</self_collide>
        <enable_wind>0</enable_wind>
        <kinematic>0</kinematic>
      </link>
      <joint name='rotor_1_joint' type='revolute'>
        <pose relative_to='base_link'>-0.212132 0.212132 0.01 0 -0 0</pose>
        <parent>base_link</parent>
        <child>rotor_1</child>
        <axis>
          <xyz>0 0 1</xyz>
          <limit>
            <lower>-1e+16</lower>
            <upper>1e+16</upper>
          </limit>
          <dynamics>
            <spring_reference>0</spring_reference>
            <spring_stiffness>0</spring_stiffness>
          </dynamics>
        </axis>
      </joint>
      <link name='rotor_1'>
        <pose relative_to='rotor_1_joint'>0 0 0 0 -0 0</pose>
        <inertial>
          <pose>0 0 0 0 -0 0</pose>
          <mass>0.005</mass>
          <inertia>
            <ixx>0.0001</ixx>
            <ixy>0</ixy>
            <ixz>0</ixz>
            <iyy>0.0001</iyy>
            <iyz>0</iyz>
            <izz>0.0001</izz>
          </inertia>
        </inertial>
        <collision name='rotor_1_collision'>
          <pose>0 0 0 0 -0 0</pose>
          <geometry>
            <cylinder>
              <length>0.005</length>
              <radius>0.195</radius>
            </cylinder>
          </geometry>
          <max_contacts>10</max_contacts>
          <surface>
            <contact>
              <ode/>
            </contact>
            <bounce/>
            <friction>
              <torsional>
                <ode/>
              </torsional>
              <ode/>
            </friction>
          </surface>
        </collision>
        <visual name='rotor_1_visual'>
          <pose>0 0 0 0 -0 0</pose>
          <geometry>
            <mesh>
              <scale>1 1 1</scale>
              <uri>model://mrs_robots_description/meshes/tarot/t650/tarot_t650_prop_low_poly.dae</uri>
            </mesh>
          </geometry>
        </visual>
        <self_collide>0</self_collide>
        <enable_wind>0</enable_wind>
        <kinematic>0</kinematic>
      </link>
      <joint name='rotor_2_joint' type='revolute'>
        <pose relative_to='base_link'>0.212132 0.212132 0.01 0 -0 0</pose>
        <parent>base_link</parent>
        <child>rotor_2</child>
        <axis>
          <xyz>0 0 1</xyz>
          <limit>
            <lower>-1e+16</lower>
            <upper>1e+16</upper>
          </limit>
          <dynamics>
            <spring_reference>0</spring_reference>
            <spring_stiffness>0</spring_stiffness>
          </dynamics>
        </axis>
      </joint>
      <link name='rotor_2'>
        <pose relative_to='rotor_2_joint'>0 0 0 0 -0 0</pose>
        <inertial>
          <pose>0 0 0 0 -0 0</pose>
          <mass>0.005</mass>
          <inertia>
            <ixx>0.0001</ixx>
            <ixy>0</ixy>
            <ixz>0</ixz>
            <iyy>0.0001</iyy>
            <iyz>0</iyz>
            <izz>0.0001</izz>
          </inertia>
        </inertial>
        <collision name='rotor_2_collision'>
          <pose>0 0 0 0 -0 0</pose>
          <geometry>
            <cylinder>
              <length>0.005</length>
              <radius>0.195</radius>
            </cylinder>
          </geometry>
          <max_contacts>10</max_contacts>
          <surface>
            <contact>
              <ode/>
            </contact>
            <bounce/>
            <friction>
              <torsional>
                <ode/>
              </torsional>
              <ode/>
            </friction>
          </surface>
        </collision>
        <visual name='rotor_2_visual'>
          <pose>0 0 0 0 -0 0</pose>
          <geometry>
            <mesh>
              <scale>-1 1 1</scale>
              <uri>model://mrs_robots_description/meshes/tarot/t650/tarot_t650_prop_low_poly.dae</uri>
            </mesh>
          </geometry>
        </visual>
        <self_collide>0</self_collide>
        <enable_wind>0</enable_wind>
        <kinematic>0</kinematic>
      </link>
      <joint name='rotor_3_joint' type='revolute'>
        <pose relative_to='base_link'>-0.212132 -0.212132 0.01 0 -0 0</pose>
        <parent>base_link</parent>
        <child>rotor_3</child>
        <axis>
          <xyz>0 0 1</xyz>
          <limit>
            <lower>-1e+16</lower>
            <upper>1e+16</upper>
          </limit>
          <dynamics>
            <spring_reference>0</spring_reference>
            <spring_stiffness>0</spring_stiffness>
          </dynamics>
        </axis>
      </joint>
      <link name='rotor_3'>
        <pose relative_to='rotor_3_joint'>0 0 0 0 -0 0</pose>
        <inertial>
          <pose>0 0 0 0 -0 0</pose>
          <mass>0.005</mass>
          <inertia>
            <ixx>0.0001</ixx>
            <ixy>0</ixy>
            <ixz>0</ixz>
            <iyy>0.0001</iyy>
            <iyz>0</iyz>
            <izz>0.0001</izz>
          </inertia>
        </inertial>
        <collision name='rotor_3_collision'>
          <pose>0 0 0 0 -0 0</pose>
          <geometry>
            <cylinder>
              <length>0.005</length>
              <radius>0.195</radius>
            </cylinder>
          </geometry>
          <max_contacts>10</max_contacts>
          <surface>
            <contact>
              <ode/>
            </contact>
            <bounce/>
            <friction>
              <torsional>
                <ode/>
              </torsional>
              <ode/>
            </friction>
          </surface>
        </collision>
        <visual name='rotor_3_visual'>
          <pose>0 0 0 0 -0 0</pose>
          <geometry>
            <mesh>
              <scale>-1 1 1</scale>
              <uri>model://mrs_robots_description/meshes/tarot/t650/tarot_t650_prop_low_poly.dae</uri>
            </mesh>
          </geometry>
        </visual>
        <self_collide>0</self_collide>
        <enable_wind>0</enable_wind>
        <kinematic>0</kinematic>
      </link>
      <joint name='uav2/imu_joint' type='revolute'>
        <pose relative_to='base_link'>0 0 0 0 -0 0</pose>
        <parent>base_link</parent>
        <child>uav2/imu_link</child>
        <axis>
          <xyz>1 0 0</xyz>
          <limit>
            <lower>0</lower>
            <upper>0</upper>
            <effort>0</effort>
            <velocity>0</velocity>
          </limit>
          <dynamics>
            <spring_reference>0</spring_reference>
            <spring_stiffness>0</spring_stiffness>
          </dynamics>
        </axis>
      </joint>
      <link name='uav2/imu_link'>
        <pose relative_to='uav2/imu_joint'>0 0 0 0 -0 0</pose>
        <inertial>
          <pose>0 0 0 0 -0 0</pose>
          <mass>0.015</mass>
          <inertia>
            <ixx>1e-05</ixx>
            <ixy>0</ixy>
            <ixz>0</ixz>
            <iyy>1e-05</iyy>
            <iyz>0</iyz>
            <izz>1e-05</izz>
          </inertia>
        </inertial>
        <self_collide>0</self_collide>
        <enable_wind>0</enable_wind>
        <kinematic>0</kinematic>
      </link>
      <plugin name='rosbag' filename='libgazebo_multirotor_base_plugin.so'>
        <robotNamespace>uav2</robotNamespace>
        <linkName>base_link</linkName>
        <rotorVelocitySlowdownSim>0.0159236</rotorVelocitySlowdownSim>
      </plugin>
      <plugin name='front_right_motor_model' filename='libgazebo_motor_model.so'>
        <robotNamespace>uav2</robotNamespace>
        <jointName>rotor_0_joint</jointName>
        <linkName>rotor_0</linkName>
        <turningDirection>ccw</turningDirection>
        <timeConstantUp>0.0125</timeConstantUp>
        <timeConstantDown>0.025</timeConstantDown>
        <maxRotVelocity>1</maxRotVelocity>
        <motorConstant>23.0</motorConstant>
        <momentConstant>0.016</momentConstant>
        <commandSubTopic>/gazebo/command/motor_speed</commandSubTopic>
        <motorNumber>0</motorNumber>
        <rotorDragCoefficient>0.1</rotorDragCoefficient>
        <rollingMomentCoefficient>1e-06</rollingMomentCoefficient>
        <motorSpeedPubTopic>/motor_speed/0</motorSpeedPubTopic>
        <rotorVelocitySlowdownSim>0.0159236</rotorVelocitySlowdownSim>
      </plugin>
      <plugin name='back_left_motor_model' filename='libgazebo_motor_model.so'>
        <robotNamespace>uav2</robotNamespace>
        <jointName>rotor_1_joint</jointName>
        <linkName>rotor_1</linkName>
        <turningDirection>ccw</turningDirection>
        <timeConstantUp>0.0125</timeConstantUp>
        <timeConstantDown>0.025</timeConstantDown>
        <maxRotVelocity>1</maxRotVelocity>
        <motorConstant>23.0</motorConstant>
        <momentConstant>0.016</momentConstant>
        <commandSubTopic>/gazebo/command/motor_speed</commandSubTopic>
        <motorNumber>1</motorNumber>
        <rotorDragCoefficient>0.1</rotorDragCoefficient>
        <rollingMomentCoefficient>1e-06</rollingMomentCoefficient>
        <motorSpeedPubTopic>/motor_speed/1</motorSpeedPubTopic>
        <rotorVelocitySlowdownSim>0.0159236</rotorVelocitySlowdownSim>
      </plugin>
      <plugin name='front_left_motor_model' filename='libgazebo_motor_model.so'>
        <robotNamespace>uav2</robotNamespace>
        <jointName>rotor_2_joint</jointName>
        <linkName>rotor_2</linkName>
        <turningDirection>cw</turningDirection>
        <timeConstantUp>0.0125</timeConstantUp>
        <timeConstantDown>0.025</timeConstantDown>
        <maxRotVelocity>1</maxRotVelocity>
        <motorConstant>23.0</motorConstant>
        <momentConstant>0.016</momentConstant>
        <commandSubTopic>/gazebo/command/motor_speed</commandSubTopic>
        <motorNumber>2</motorNumber>
        <rotorDragCoefficient>0.1</rotorDragCoefficient>
        <rollingMomentCoefficient>1e-06</rollingMomentCoefficient>
        <motorSpeedPubTopic>/motor_speed/2</motorSpeedPubTopic>
        <rotorVelocitySlowdownSim>0.0159236</rotorVelocitySlowdownSim>
      </plugin>
      <plugin name='back_right_motor_model' filename='libgazebo_motor_model.so'>
        <robotNamespace>uav2</robotNamespace>
        <jointName>rotor_3_joint</jointName>
        <linkName>rotor_3</linkName>
        <turningDirection>cw</turningDirection>
        <timeConstantUp>0.0125</timeConstantUp>
        <timeConstantDown>0.025</timeConstantDown>
        <maxRotVelocity>1</maxRotVelocity>
        <motorConstant>23.0</motorConstant>
        <momentConstant>0.016</momentConstant>
        <commandSubTopic>/gazebo/command/motor_speed</commandSubTopic>
        <motorNumber>3</motorNumber>
        <rotorDragCoefficient>0.1</rotorDragCoefficient>
        <rollingMomentCoefficient>1e-06</rollingMomentCoefficient>
        <motorSpeedPubTopic>/motor_speed/3</motorSpeedPubTopic>
        <rotorVelocitySlowdownSim>0.0159236</rotorVelocitySlowdownSim>
      </plugin>
      <plugin name='mavlink_interface' filename='libgazebo_mavlink_interface.so'>
        <robotNamespace>uav2</robotNamespace>
        <imuSubTopic>/imu</imuSubTopic>
        <magSubTopic>/mag</magSubTopic>
        <baroSubTopic>/baro</baroSubTopic>
        <mavlink_addr>INADDR_ANY</mavlink_addr>
        <mavlink_udp_port>14562</mavlink_udp_port>
        <mavlink_tcp_port>4562</mavlink_tcp_port>
        <serialEnabled>0</serialEnabled>
        <serialDevice>/dev/ttyACM0</serialDevice>
        <baudRate>921600</baudRate>
        <qgc_addr>INADDR_ANY</qgc_addr>
        <qgc_udp_port>14550</qgc_udp_port>
        <sdk_addr>INADDR_ANY</sdk_addr>
        <sdk_udp_port>14540</sdk_udp_port>
        <hil_mode>0</hil_mode>
        <hil_state_level>0</hil_state_level>
        <vehicle_is_tailsitter>0</vehicle_is_tailsitter>
        <send_vision_estimation>0</send_vision_estimation>
        <send_odometry>0</send_odometry>
        <enable_lockstep>1</enable_lockstep>
        <use_tcp>1</use_tcp>
        <motorSpeedCommandPubTopic>/gazebo/command/motor_speed</motorSpeedCommandPubTopic>
        <control_channels>
          <channel name='rotor1'>
            <input_index>0</input_index>
            <input_offset>0</input_offset>
            <input_scaling>1</input_scaling>
            <zero_position_disarmed>0</zero_position_disarmed>
            <zero_position_armed>0.15</zero_position_armed>
            <joint_control_type>velocity</joint_control_type>
          </channel>
          <channel name='rotor2'>
            <input_index>1</input_index>
            <input_offset>0</input_offset>
            <input_scaling>1</input_scaling>
            <zero_position_disarmed>0</zero_position_disarmed>
            <zero_position_armed>0.15</zero_position_armed>
            <joint_control_type>velocity</joint_control_type>
          </channel>
          <channel name='rotor3'>
            <input_index>2</input_index>
            <input_offset>0</input_offset>
            <input_scaling>1</input_scaling>
            <zero_position_disarmed>0</zero_position_disarmed>
            <zero_position_armed>0.15</zero_position_armed>
            <joint_control_type>velocity</joint_control_type>
          </channel>
          <channel name='rotor4'>
            <input_index>3</input_index>
            <input_offset>0</input_offset>
            <input_scaling>1</input_scaling>
            <zero_position_disarmed>0</zero_position_disarmed>
            <zero_position_armed>0.15</zero_position_armed>
            <joint_control_type>velocity</joint_control_type>
          </channel>
          <channel name='rotor5'>
            <input_index>4</input_index>
            <input_offset>0</input_offset>
            <input_scaling>1</input_scaling>
            <zero_position_disarmed>0</zero_position_disarmed>
            <zero_position_armed>0.15</zero_position_armed>
            <joint_control_type>velocity</joint_control_type>
          </channel>
          <channel name='rotor6'>
            <input_index>5</input_index>
            <input_offset>0</input_offset>
            <input_scaling>1</input_scaling>
            <zero_position_disarmed>0</zero_position_disarmed>
            <zero_position_armed>0.15</zero_position_armed>
            <joint_control_type>velocity</joint_control_type>
          </channel>
          <channel name='rotor7'>
            <input_index>6</input_index>
            <input_offset>0</input_offset>
            <input_scaling>1</input_scaling>
            <zero_position_disarmed>0</zero_position_disarmed>
            <zero_position_armed>0.15</zero_position_armed>
            <joint_control_type>velocity</joint_control_type>
          </channel>
          <channel name='rotor8'>
            <input_index>7</input_index>
            <input_offset>0</input_offset>
            <input_scaling>1</input_scaling>
            <zero_position_disarmed>0</zero_position_disarmed>
            <zero_position_armed>0.15</zero_position_armed>
            <joint_control_type>velocity</joint_control_type>
          </channel>
        </control_channels>
      </plugin>
      <link name='gps0_link'>
        <pose>0 0 0 0 -0 0</pose>
        <inertial>
          <pose>0 0 0 0 -0 0</pose>
          <mass>0.01</mass>
          <inertia>
            <ixx>2.1733e-06</ixx>
            <ixy>0</ixy>
            <ixz>0</ixz>
            <iyy>2.1733e-06</iyy>
            <iyz>0</iyz>
            <izz>1.8e-07</izz>
          </inertia>
        </inertial>
        <sensor name='gps' type='gps'>
          <pose>0 0 0 0 -0 0</pose>
          <plugin name='gps_plugin' filename='libgazebo_gps_plugin.so'>
            <robotNamespace>uav2</robotNamespace>
            <gpsNoise>1</gpsNoise>
            <gpsXYRandomWalk>2.0</gpsXYRandomWalk>
            <gpsZRandomWalk>4.0</gpsZRandomWalk>
            <gpsXYNoiseDensity>0.0002</gpsXYNoiseDensity>
            <gpsZNoiseDensity>0.0004</gpsZNoiseDensity>
            <gpsVXYNoiseDensity>0.2</gpsVXYNoiseDensity>
            <gpsVZNoiseDensity>0.4</gpsVZNoiseDensity>
            <update_rate>10</update_rate>
            <topic>gps0</topic>
          </plugin>
          <gps/>
        </sensor>
        <self_collide>0</self_collide>
        <enable_wind>0</enable_wind>
        <kinematic>0</kinematic>
      </link>
      <joint name='gps0_joint' type='fixed'>
        <parent>base_link</parent>
        <child>gps0_link</child>
      </joint>
      <plugin name='magnetometer_plugin' filename='libMRSGazeboMagnetometerPlugin.so'>
        <robotNamespace>uav2</robotNamespace>
        <pubRate>100</pubRate>
        <noiseDensity>0.0004</noiseDensity>
        <randomWalk>6.4e-06</randomWalk>
        <biasCorrelationTime>600</biasCorrelationTime>
        <magTopic>/mag</magTopic>
      </plugin>
      <plugin name='groundtruth_plugin' filename='libgazebo_groundtruth_plugin.so'>
        <robotNamespace>uav2</robotNamespace>
        <homeLatitude>0.0</homeLatitude>
        <homeLongitude>0.0</homeLongitude>
        <homeAltitude>0.0</homeAltitude>
      </plugin>
      <plugin name='barometer_plugin' filename='libgazebo_barometer_plugin.so'>
        <robotNamespace>uav2</robotNamespace>
        <pubRate>50</pubRate>
        <baroTopic>/baro</baroTopic>
        <baroDriftPaPerSec>0</baroDriftPaPerSec>
      </plugin>
      <static>0</static>
      <plugin name='rotors_gazebo_imu_plugin' filename='libgazebo_imu_plugin.so'>
        <robotNamespace>uav2</robotNamespace>
        <linkName>uav2/imu_link</linkName>
        <imuTopic>/imu</imuTopic>
        <gyroscopeNoiseDensity>0.00018665</gyroscopeNoiseDensity>
        <gyroscopeRandomWalk>3.8785e-05</gyroscopeRandomWalk>
        <gyroscopeBiasCorrelationTime>1000.0</gyroscopeBiasCorrelationTime>
        <gyroscopeTurnOnBiasSigma>0.0087</gyroscopeTurnOnBiasSigma>
        <accelerometerNoiseDensity>0.00186</accelerometerNoiseDensity>
        <accelerometerRandomWalk>0.006</accelerometerRandomWalk>
        <accelerometerBiasCorrelationTime>300.0</accelerometerBiasCorrelationTime>
        <accelerometerTurnOnBiasSigma>0.196</accelerometerTurnOnBiasSigma>
      </plugin>
      <pose>4 21.45 0.3 0 -0 0</pose>
    </model>
    <state world_name='default'>
      <sim_time>8824 88000000</sim_time>
      <real_time>162 301169080</real_time>
      <wall_time>1645014981 57401785</wall_time>
      <iterations>39176</iterations>
      <model name='ground_plane'>
        <pose>1.34392 -1.97365 0 0 -0 0</pose>
        <scale>1 1 1</scale>
        <link name='link'>
          <pose>1.34392 -1.97365 0 0 -0 0</pose>
          <velocity>0 0 0 0 -0 0</velocity>
          <acceleration>0 0 0 0 -0 0</acceleration>
          <wrench>0 0 0 0 -0 0</wrench>
        </link>
      </model>
      <model name='the_void'>
        <pose>-1000 -1000 0 0 -0 0</pose>
        <scale>1 1 1</scale>
        <link name='link'>
          <pose>-1000 -1000 0.1 0 -0 0</pose>
          <velocity>0 0 0 0 -0 0</velocity>
          <acceleration>0 0 0 0 -0 0</acceleration>
          <wrench>0 0 0 0 -0 0</wrench>
        </link>
      </model>
      <model name='uav1'>
        <pose>10.7828 -1.01463 1.7287 -0.001443 0.002057 0.255998</pose>
        <scale>1 1 1</scale>
        <link name='base_link'>
          <pose>10.7828 -1.01463 1.7287 -0.001443 0.002057 0.255998</pose>
          <velocity>0.017467 0.003129 0.006443 0.000549 -0.001008 -0.000208</velocity>
          <acceleration>0.014741 0.018603 -0.003469 0.087616 0.247204 -0.007817</acceleration>
          <wrench>0.051592 0.065111 -0.012142 0 -0 0</wrench>
        </link>
        <link name='gps0_link'>
          <pose>10.7828 -1.01463 1.7287 -0.001443 0.002057 0.255998</pose>
          <velocity>0.017467 0.003129 0.006443 0.000549 -0.001008 -0.000208</velocity>
          <acceleration>0.014741 0.018603 -0.003469 0.087607 0.247188 -0.000689</acceleration>
          <wrench>0.000147 0.000186 -3.5e-05 0 -0 0</wrench>
        </link>
        <link name='rotor_0'>
          <pose>11.0417 -1.16611 1.73857 -0.000734 0.002394 0.568138</pose>
          <velocity>0.017426 0.00307 0.006621 0.062808 0.072756 0.912412</velocity>
          <acceleration>0.01603 0.015795 -0.08075 -0.050318 0.273886 -0.000441</acceleration>
          <wrench>8e-05 7.9e-05 -0.000404 0 -0 0</wrench>
        </link>
        <link name='rotor_1'>
          <pose>10.5239 -0.863101 1.73883 -0.001601 -0.001926 -1.58196</pose>
          <velocity>0.017489 0.003177 0.006265 0.062869 0.072866 0.964105</velocity>
          <acceleration>0.018394 0.019659 0.073802 -0.050759 0.273982 -0.00044</acceleration>
          <wrench>9.2e-05 9.8e-05 0.000369 0 -0 0</wrench>
        </link>
        <link name='rotor_2'>
          <pose>10.9343 -0.755673 1.73795 0.001459 0.002055 1.48723</pose>
          <velocity>0.017512 0.003092 0.006738 -0.061785 -0.075537 -0.888553</velocity>
          <acceleration>0.018969 0.016655 -0.018243 0.227332 0.23267 -0.00082</acceleration>
          <wrench>9.5e-05 8.3e-05 -9.1e-05 0 -0 0</wrench>
        </link>
        <link name='rotor_3'>
          <pose>10.6313 -1.27354 1.73944 -0.002105 0.001384 -0.119622</pose>
          <velocity>0.017403 0.003155 0.006148 -0.061775 -0.075519 -0.890906</velocity>
          <acceleration>0.015455 0.018799 0.011286 0.227466 0.232659 -0.00082</acceleration>
          <wrench>7.7e-05 9.4e-05 5.6e-05 0 -0 0</wrench>
        </link>
        <link name='uav1/imu_link'>
          <pose>10.7828 -1.01463 1.7287 -0.001443 0.002057 0.255998</pose>
          <velocity>0.017467 0.003129 0.006443 0.000557 -0.001006 -0.000208</velocity>
          <acceleration>0.014741 0.018603 -0.003469 0.091278 0.248149 -0.007521</acceleration>
          <wrench>0.000221 0.000279 -5.2e-05 0 -0 0</wrench>
        </link>
      </model>
      <model name='uav2'>
        <pose>8.72689 2.16083 0.072791 3.1379 0.000518 -1.43124</pose>
        <scale>1 1 1</scale>
        <link name='base_link'>
          <pose>8.72689 2.16083 0.072791 3.1379 0.000518 -1.43124</pose>
          <velocity>0.022831 0 -0.100386 -2e-06 0.300074 0</velocity>
          <acceleration>9.81764 8.3e-05 0.001194 -0.00128 1.51326 -5e-06</acceleration>
          <wrench>34.3617 0.00029 0.004179 0 -0 0</wrench>
        </link>
        <link name='gps0_link'>
          <pose>8.72689 2.16083 0.07279 3.13792 0.000516 -1.43124</pose>
          <velocity>0.020934 0 -0.100496 -1e-06 0.307514 -1e-06</velocity>
          <acceleration>9.34664 6.4e-05 -0.032803 3.14028 -0.025035 -3.14152</acceleration>
          <wrench>0.093466 1e-06 -0.000328 0 -0 0</wrench>
        </link>
        <link name='rotor_0'>
          <pose>8.96647 1.98027 0.0619 3.13845 0.00197 -1.01121</pose>
          <velocity>0.016466 0 -0.174048 -3e-06 0.307202 -0</velocity>
          <acceleration>7.52267 0.000144 -36.9342 3.14019 -0.153704 -3.14159</acceleration>
          <wrench>0.037613 1e-06 -0.184671 0 -0 0</wrench>
        </link>
        <link name='rotor_1'>
          <pose>8.48725 2.34139 0.063677 3.13884 -0.002485 -2.30441</pose>
          <velocity>0.019247 1e-06 -0.026804 4.5e-05 0.307288 0</velocity>
          <acceleration>8.07959 0.000197 36.9108 -3.13102 -0.175135 3.14149</acceleration>
          <wrench>0.040398 1e-06 0.184554 0 -0 0</wrench>
        </link>
        <link name='rotor_2'>
          <pose>8.54627 1.92125 0.063459 3.14128 -0.003695 -3.05568</pose>
          <velocity>0.018904 1e-06 -0.044953 0.000102 0.307386 -1e-06</velocity>
          <acceleration>8.01099 0.000231 27.8124 -3.11672 -0.199741 3.1414</acceleration>
          <wrench>0.040055 1e-06 0.139062 0 -0 0</wrench>
        </link>
        <link name='rotor_3'>
          <pose>8.90744 2.40041 0.062119 -3.14135 -0.0037 3.0766</pose>
          <velocity>0.016808 1e-06 -0.155946 5e-05 0.307452 -1e-06</velocity>
          <acceleration>7.59095 0.00019 -27.8473 -3.1299 -0.216192 3.14148</acceleration>
          <wrench>0.037955 1e-06 -0.139236 0 -0 0</wrench>
        </link>
        <link name='uav2/imu_link'>
          <pose>8.72689 2.16083 0.07279 3.13792 0.000516 -1.43124</pose>
          <velocity>0.020932 0 -0.100497 -1e-06 0.307511 -1e-06</velocity>
          <acceleration>9.3459 6.4e-05 -0.032793 3.14031 -0.024574 -3.14153</acceleration>
          <wrench>0.140188 1e-06 -0.000492 0 -0 0</wrench>
        </link>
      </model>
      <model name='wall_32_pose_90_narrow'>
        <pose>0.590401 68.8744 0 0 -0 0</pose>
        <scale>1 1 1</scale>
        <link name='link'>
          <pose>0.590401 68.8744 0 0 -0 0</pose>
          <velocity>0 0 0 0 -0 0</velocity>
          <acceleration>0 0 0 0 -0 0</acceleration>
          <wrench>0 0 0 0 -0 0</wrench>
        </link>
      </model>
      <light name='sun'>
        <pose>0 0 1000 0.4 0.2 0</pose>
      </light>
    </state>
    <model name='wall_32_pose_90_narrow'>
      <static>1</static>
      <link name='link'>
        <collision name='collision1'>
          <pose>0 0 3.25 1.5708 -0 0</pose>
          <geometry>
            <box>
              <size>32 7.5 0.05</size>
            </box>
          </geometry>
          <max_contacts>10</max_contacts>
          <surface>
            <contact>
              <ode/>
            </contact>
            <bounce/>
            <friction>
              <torsional>
                <ode/>
              </torsional>
              <ode/>
            </friction>
          </surface>
        </collision>
        <collision name='collision2'>
          <pose>16 16 3.25 1.5708 -0 1.5708</pose>
          <geometry>
            <box>
              <size>32 7.5 0.05</size>
            </box>
          </geometry>
          <max_contacts>10</max_contacts>
          <surface>
            <contact>
              <ode/>
            </contact>
            <bounce/>
            <friction>
              <torsional>
                <ode/>
              </torsional>
              <ode/>
            </friction>
          </surface>
        </collision>
        <collision name='collision3'>
          <pose>0 32 3.25 1.5708 -0 -3.14159</pose>
          <geometry>
            <box>
              <size>32 7.5 0.05</size>
            </box>
          </geometry>
          <max_contacts>10</max_contacts>
          <surface>
            <contact>
              <ode/>
            </contact>
            <bounce/>
            <friction>
              <torsional>
                <ode/>
              </torsional>
              <ode/>
            </friction>
          </surface>
        </collision>
        <collision name='collision4'>
          <pose>-16 16 3.25 1.5708 -0 1.5708</pose>
          <geometry>
            <box>
              <size>32 7.5 0.05</size>
            </box>
          </geometry>
          <max_contacts>10</max_contacts>
          <surface>
            <contact>
              <ode/>
            </contact>
            <bounce/>
            <friction>
              <torsional>
                <ode/>
              </torsional>
              <ode/>
            </friction>
          </surface>
        </collision>
        <visual name='visual1'>
          <pose>0 0 3.25 1.5708 -0 0</pose>
          <geometry>
            <box>
              <size>32 7.5 0.05</size>
            </box>
          </geometry>
        </visual>
        <visual name='visual2'>
          <pose>16 16 3.25 1.5708 -0 1.5708</pose>
          <geometry>
            <box>
              <size>32 7.5 0.05</size>
            </box>
          </geometry>
        </visual>
        <visual name='visual3'>
          <pose>0 32 3.25 1.5708 -0 -3.14159</pose>
          <geometry>
            <box>
              <size>32 7.5 0.05</size>
            </box>
          </geometry>
        </visual>
        <visual name='visual4'>
          <pose>-16 16 3.25 1.5708 -0 1.5708</pose>
          <geometry>
            <box>
              <size>32 7.5 0.05</size>
            </box>
          </geometry>
        </visual>
        <collision name='collision5'>
          <pose>0 12 3.25 1.5708 -0 0</pose>
          <geometry>
            <box>
              <size>8 7.5 0.05</size>
            </box>
          </geometry>
          <max_contacts>10</max_contacts>
          <surface>
            <contact>
              <ode/>
            </contact>
            <bounce/>
            <friction>
              <torsional>
                <ode/>
              </torsional>
              <ode/>
            </friction>
          </surface>
        </collision>
        <collision name='collision6'>
          <pose>4 16 3.25 1.5708 -0 1.5708</pose>
          <geometry>
            <box>
              <size>8 7.5 0.05</size>
            </box>
          </geometry>
          <max_contacts>10</max_contacts>
          <surface>
            <contact>
              <ode/>
            </contact>
            <bounce/>
            <friction>
              <torsional>
                <ode/>
              </torsional>
              <ode/>
            </friction>
          </surface>
        </collision>
        <collision name='collision7'>
          <pose>0 20 3.25 1.5708 -0 -3.14159</pose>
          <geometry>
            <box>
              <size>8 7.5 0.05</size>
            </box>
          </geometry>
          <max_contacts>10</max_contacts>
          <surface>
            <contact>
              <ode/>
            </contact>
            <bounce/>
            <friction>
              <torsional>
                <ode/>
              </torsional>
              <ode/>
            </friction>
          </surface>
        </collision>
        <collision name='collision8'>
          <pose>-4 16 3.25 1.5708 -0 1.5708</pose>
          <geometry>
            <box>
              <size>8 7.5 0.05</size>
            </box>
          </geometry>
          <max_contacts>10</max_contacts>
          <surface>
            <contact>
              <ode/>
            </contact>
            <bounce/>
            <friction>
              <torsional>
                <ode/>
              </torsional>
              <ode/>
            </friction>
          </surface>
        </collision>
        <visual name='visual5'>
          <pose>0 12 3.25 1.5708 -0 0</pose>
          <geometry>
            <box>
              <size>8 7.5 0.05</size>
            </box>
          </geometry>
        </visual>
        <visual name='visual6'>
          <pose>4 16 3.25 1.5708 -0 1.5708</pose>
          <geometry>
            <box>
              <size>8 7.5 0.05</size>
            </box>
          </geometry>
        </visual>
        <visual name='visual7'>
          <pose>0 20 3.25 1.5708 -0 -3.14159</pose>
          <geometry>
            <box>
              <size>8 7.5 0.05</size>
            </box>
          </geometry>
        </visual>
        <visual name='visual8'>
          <pose>-4 16 3.25 1.5708 -0 1.5708</pose>
          <geometry>
            <box>
              <size>8 7.5 0.05</size>
            </box>
          </geometry>
        </visual>
        <collision name='fourunitscollision1'>
          <pose>0 8 3.25 1.5708 -0 0</pose>
          <geometry>
            <box>
              <size>4 7.5 0.05</size>
            </box>
          </geometry>
          <max_contacts>10</max_contacts>
          <surface>
            <contact>
              <ode/>
            </contact>
            <bounce/>
            <friction>
              <torsional>
                <ode/>
              </torsional>
              <ode/>
            </friction>
          </surface>
        </collision>
        <collision name='fourunitscollision2'>
          <pose>2 10 3.25 1.5708 -0 1.5708</pose>
          <geometry>
            <box>
              <size>4 7.5 0.05</size>
            </box>
          </geometry>
          <max_contacts>10</max_contacts>
          <surface>
            <contact>
              <ode/>
            </contact>
            <bounce/>
            <friction>
              <torsional>
                <ode/>
              </torsional>
              <ode/>
            </friction>
          </surface>
        </collision>
        <collision name='fourunitscollision3'>
          <pose>-2 10 3.25 1.5708 -0 1.5708</pose>
          <geometry>
            <box>
              <size>4 7.5 0.05</size>
            </box>
          </geometry>
          <max_contacts>10</max_contacts>
          <surface>
            <contact>
              <ode/>
            </contact>
            <bounce/>
            <friction>
              <torsional>
                <ode/>
              </torsional>
              <ode/>
            </friction>
          </surface>
        </collision>
        <visual name='fourunitsvisual1'>
          <pose>0 8 3.25 1.5708 -0 0</pose>
          <geometry>
            <box>
              <size>4 7.5 0.05</size>
            </box>
          </geometry>
        </visual>
        <visual name='fourunitsvisual2'>
          <pose>2 10 3.25 1.5708 -0 1.5708</pose>
          <geometry>
            <box>
              <size>4 7.5 0.05</size>
            </box>
          </geometry>
        </visual>
        <visual name='fourunitsvisual3'>
          <pose>-2 10 3.25 1.5708 -0 1.5708</pose>
          <geometry>
            <box>
              <size>4 7.5 0.05</size>
            </box>
          </geometry>
        </visual>
        <collision name='fourunitscollision4'>
          <pose>0 4 3.25 1.5708 -0 0</pose>
          <geometry>
            <box>
              <size>4 7.5 0.05</size>
            </box>
          </geometry>
          <max_contacts>10</max_contacts>
          <surface>
            <contact>
              <ode/>
            </contact>
            <bounce/>
            <friction>
              <torsional>
                <ode/>
              </torsional>
              <ode/>
            </friction>
          </surface>
        </collision>
        <collision name='fourunitscollision5'>
          <pose>2 2 3.25 1.5708 -0 1.5708</pose>
          <geometry>
            <box>
              <size>4 7.5 0.05</size>
            </box>
          </geometry>
          <max_contacts>10</max_contacts>
          <surface>
            <contact>
              <ode/>
            </contact>
            <bounce/>
            <friction>
              <torsional>
                <ode/>
              </torsional>
              <ode/>
            </friction>
          </surface>
        </collision>
        <collision name='fourunitscollision6'>
          <pose>-2 2 3.25 1.5708 -0 1.5708</pose>
          <geometry>
            <box>
              <size>4 7.5 0.05</size>
            </box>
          </geometry>
          <max_contacts>10</max_contacts>
          <surface>
            <contact>
              <ode/>
            </contact>
            <bounce/>
            <friction>
              <torsional>
                <ode/>
              </torsional>
              <ode/>
            </friction>
          </surface>
        </collision>
        <visual name='fourunitsvisual4'>
          <pose>0 4 3.25 1.5708 -0 0</pose>
          <geometry>
            <box>
              <size>4 7.5 0.05</size>
            </box>
          </geometry>
        </visual>
        <visual name='fourunitsvisual5'>
          <pose>2 2 3.25 1.5708 -0 1.5708</pose>
          <geometry>
            <box>
              <size>4 7.5 0.05</size>
            </box>
          </geometry>
        </visual>
        <visual name='fourunitsvisual6'>
          <pose>-2 2 3.25 1.5708 -0 1.5708</pose>
          <geometry>
            <box>
              <size>4 7.5 0.05</size>
            </box>
          </geometry>
        </visual>
        <self_collide>0</self_collide>
        <enable_wind>0</enable_wind>
        <kinematic>0</kinematic>
      </link>
      <pose>0.590401 -11.0622 0 0 -0 0</pose>
    </model>
  </world>
</sdf>
